Workbook

Sheet original
A1: Click on the unit name for its home page | B1: [Gender] | C1: ALL AGES | D1: Both | E1: Males and | F1: Under | G1: 5-- | H1: 10-- | I1: 15-- | J1: 20-- | K1: 25-- | L1: 30-- | M1: 35-- | N1: 40-- | O1: 45-- | P1: 50-- | Q1: 55-- | R1: 60-- | S1: 65-- | T1: 70-- | U1: 75-- | V1: 80-- | W1: 85-- | X1: 90-- | Y1: 95-- | Z1: 100 and upwds
D2: Sexes. | E2: Females. | F2: 5 Years. | G2: [4] | H2: [5] | I2: [6] | J2: [7] | K2: [8] | L2: [9] | M2: [10] | N2: [11] | O2: [12] | P2: [13] | Q2: [14] | R2: [15] | S2: [16] | T2: [17] | U2: [18] | V2: [19] | W2: [20] | X2: [21] | Y2: [22] | Z2: [23]
A3: If | D3: [1] | E3: [2] | F3: [3]
A4: appears click for more detailed statistics
A9: #VALUE!
A16: England Country Total | C16: M. | D16: 16,738,693 | E16: 8,186,432 | F16: 1,097,843 | G16: 977,548 | H16: 897,780 | I16: 813,884 | J16: 741,867 | K16: 653,224 | L16: 577,125 | M16: 496,789 | N16: 443,503 | O16: 367,476 | P16: 323,381 | Q16: 237,153 | R16: 211,152 | S16: 140,741 | T16: 106,363 | U16: 59,831 | V16: 28,888 | W16: 9,414 | X16: 2,010 | Y16: 390 | Z16: 70
C17: F. | D17: - | E17: 8,552,261 | F17: 1,094,404 | G17: 970,692 | H17: 885,089 | I17: 826,538 | J17: 817,923 | K17: 724,953 | L17: 618,997 | M17: 521,386 | N17: 464,467 | O17: 380,793 | P17: 340,083 | Q17: 252,887 | R17: 236,051 | S17: 162,968 | T17: 125,084 | U17: 74,242 | V17: 37,964 | W17: 13,411 | X17: 3,464 | Y17: 759 | Z17: 106
A18: Bedfordshire Poor Law/Registration County | B18: #VALUE! | C18: M. | D18: 129,805 | E18: 62,539 | F18: 9,165 | G18: 8,214 | H18: 7,233 | I18: 6,393 | J18: 5,155 | K18: 4,565 | L18: 4,021 | M18: 3,577 | N18: 3,086 | O18: 2,753 | P18: 2,456 | Q18: 1,801 | R18: 1,575 | S18: 969 | T18: 753 | U18: 503 | V18: 242 | W18: 64 | X18: 14 | Y18: 0 | Z18: 0
C19: F. | D19: - | E19: 67,266 | F19: 9,189 | G19: 8,075 | H19: 7,338 | I19: 7,169 | J19: 6,266 | K19: 5,448 | L19: 4,624 | M19: 3,803 | N19: 3,358 | O19: 2,725 | P19: 2,493 | Q19: 1,993 | R19: 1,833 | S19: 1,176 | T19: 891 | U19: 531 | V19: 266 | W19: 65 | X19: 20 | Y19: 3 | Z19: 0
A20: Berkshire Poor Law/Registration County | B20: #VALUE! | C20: M. | D20: 199,224 | E20: 99,486 | F20: 12,888 | G20: 12,119 | H20: 11,149 | I20: 10,135 | J20: 8,313 | K20: 7,208 | L20: 6,374 | M20: 5,892 | N20: 5,228 | O20: 4,536 | P20: 4,145 | Q20: 3,243 | R20: 2,913 | S20: 1,964 | T20: 1,637 | U20: 973 | V20: 538 | W20: 181 | X20: 45 | Y20: 5 | Z20: 0
C21: F. | D21: - | E21: 99,738 | F21: 12,784 | G21: 12,140 | H21: 10,628 | I21: 9,364 | J21: 8,546 | K21: 7,673 | L21: 6,642 | M21: 5,960 | N21: 5,283 | O21: 4,464 | P21: 4,022 | Q21: 3,244 | R21: 2,989 | S21: 2,210 | T21: 1,861 | U21: 1,083 | V21: 580 | W21: 195 | X21: 58 | Y21: 10 | Z21: 2
A22: Buckinghamshire Poor Law/Registration County | B22: #VALUE! | C22: M. | D22: 143,655 | E22: 70,928 | F22: 9,891 | G22: 8,837 | H22: 8,170 | I22: 7,312 | J22: 5,576 | K22: 4,932 | L22: 4,277 | M22: 4,086 | N22: 3,573 | O22: 3,189 | P22: 2,895 | Q22: 2,227 | R22: 2,151 | S22: 1,486 | T22: 1,194 | U22: 667 | V22: 326 | W22: 115 | X22: 19 | Y22: 5 | Z22: 0
C23: F. | D23: - | E23: 72,727 | F23: 9,716 | G23: 8,738 | H23: 7,736 | I23: 6,685 | J23: 6,181 | K23: 5,575 | L23: 4,702 | M23: 4,313 | N23: 3,802 | O23: 3,263 | P23: 3,060 | Q23: 2,363 | R23: 2,366 | S23: 1,631 | T23: 1,314 | U23: 781 | V23: 358 | W23: 112 | X23: 22 | Y23: 9 | Z23: 0
A24: Cambridgeshire Poor Law/Registration County | B24: #VALUE! | C24: M. | D24: 191,894 | E24: 95,704 | F24: 13,120 | G24: 12,071 | H24: 10,453 | I24: 9,922 | J24: 8,959 | K24: 7,185 | L24: 6,409 | M24: 5,353 | N24: 4,669 | O24: 4,228 | P24: 3,827 | Q24: 2,840 | R24: 2,685 | S24: 1,583 | T24: 1,123 | U24: 772 | V24: 357 | W24: 117 | X24: 25 | Y24: 6 | Z24: 0
C25: F. | D25: - | E25: 96,190 | F25: 12,979 | G25: 11,819 | H25: 10,446 | I25: 9,497 | J25: 8,719 | K25: 7,605 | L25: 6,565 | M25: 5,636 | N25: 4,774 | O25: 4,075 | P25: 3,727 | Q25: 2,919 | R25: 2,764 | S25: 1,676 | T25: 1,336 | U25: 950 | V25: 485 | W25: 166 | X25: 39 | Y25: 11 | Z25: 2
A26: Cheshire Poor Law/Registration County | B26: #VALUE! | C26: M. | D26: 423,526 | E26: 207,008 | F26: 27,723 | G26: 24,973 | H26: 23,335 | I26: 20,877 | J26: 18,830 | K26: 16,820 | L26: 14,775 | M26: 12,645 | N26: 11,283 | O26: 9,316 | P26: 8,079 | Q26: 5,491 | R26: 5,020 | S26: 3,218 | T26: 2,407 | U26: 1,390 | V26: 581 | W26: 194 | X26: 44 | Y26: 7 | Z26: 0
C27: F. | D27: - | E27: 216,518 | F27: 27,553 | G27: 24,662 | H27: 23,258 | I27: 22,132 | J27: 21,846 | K27: 18,941 | L27: 15,646 | M27: 12,919 | N27: 11,662 | O27: 9,387 | P27: 8,133 | Q27: 5,976 | R27: 5,490 | S27: 3,698 | T27: 2,675 | U27: 1,467 | V27: 744 | W27: 242 | X27: 77 | Y27: 8 | Z27: 2
A28: Cornwall Poor Law/Registration County | B28: #VALUE! | C28: M. | D28: 356,641 | E28: 172,193 | F28: 24,308 | G28: 23,518 | H28: 20,605 | I28: 18,553 | J28: 14,567 | K28: 11,915 | L28: 9,977 | M28: 8,992 | N28: 8,223 | O28: 7,433 | P28: 6,578 | Q28: 5,259 | R28: 4,388 | S28: 3,167 | T28: 2,423 | U28: 1,378 | V28: 659 | W28: 198 | X28: 41 | Y28: 11 | Z28: 0
C29: F. | D29: - | E29: 184,448 | F29: 23,541 | G29: 22,611 | H29: 20,184 | I29: 18,442 | J29: 16,341 | K29: 13,854 | L29: 11,603 | M29: 10,213 | N29: 9,283 | O29: 8,266 | P29: 7,576 | Q29: 6,156 | R29: 5,452 | S29: 4,156 | T29: 3,235 | U29: 1,976 | V29: 1,029 | W29: 426 | X29: 85 | Y29: 16 | Z29: 3
A30: County Durham Poor Law/Registration County | B30: #VALUE! | C30: M. | D30: 411,679 | E30: 207,088 | F30: 30,220 | G30: 25,427 | H30: 22,818 | I30: 20,552 | J30: 19,836 | K30: 17,311 | L30: 14,977 | M30: 12,445 | N30: 10,713 | O30: 8,611 | P30: 7,416 | Q30: 5,134 | R30: 4,450 | S30: 2,966 | T30: 2,113 | U30: 1,193 | V30: 661 | W30: 187 | X30: 41 | Y30: 14 | Z30: 3
C31: F. | D31: - | E31: 204,591 | F31: 29,708 | G31: 24,635 | H31: 22,073 | I31: 19,608 | J31: 18,842 | K31: 16,944 | L31: 14,294 | M31: 12,048 | N31: 10,577 | O31: 8,648 | P31: 7,510 | Q31: 5,492 | R31: 4,901 | S31: 3,571 | T31: 2,620 | U31: 1,744 | V31: 897 | W31: 349 | X31: 98 | Y31: 26 | Z31: 6
A32: Cumberland Poor Law/Registration County | B32: #VALUE! | C32: M. | D32: 195,492 | E32: 96,244 | F32: 12,707 | G32: 11,314 | H32: 10,981 | I32: 9,835 | J32: 8,507 | K32: 7,346 | L32: 6,284 | M32: 5,642 | N32: 5,042 | O32: 4,163 | P32: 3,837 | Q32: 2,963 | R32: 2,799 | S32: 1,944 | T32: 1,430 | U32: 818 | V32: 447 | W32: 140 | X32: 36 | Y32: 6 | Z32: 3
C33: F. | D33: - | E33: 99,248 | F33: 12,385 | G33: 11,348 | H33: 10,412 | I33: 9,602 | J33: 9,008 | K33: 7,920 | L33: 6,697 | M33: 5,871 | N33: 5,295 | O33: 4,345 | P33: 4,140 | Q33: 3,194 | R33: 2,996 | S33: 2,336 | T33: 1,797 | U33: 1,072 | V33: 531 | W33: 228 | X33: 57 | Y33: 14 | Z33: 0
A34: Derbyshire Poor Law/Registration County | B34: #VALUE! | C34: M. | D34: 260,693 | E34: 129,501 | F34: 16,685 | G34: 15,642 | H34: 14,582 | I34: 13,237 | J34: 11,687 | K34: 9,930 | L34: 8,492 | M34: 7,684 | N34: 6,938 | O34: 6,053 | P34: 5,306 | Q34: 3,969 | R34: 3,486 | S34: 2,459 | T34: 1,706 | U34: 948 | V34: 495 | W34: 165 | X34: 31 | Y34: 5 | Z34: 1
C35: F. | D35: - | E35: 131,192 | F35: 16,966 | G35: 15,352 | H35: 14,668 | I35: 12,993 | J35: 12,012 | K35: 10,639 | L35: 8,827 | M35: 7,597 | N35: 7,139 | O35: 5,950 | P35: 5,299 | Q35: 4,070 | R35: 3,484 | S35: 2,605 | T35: 1,863 | U35: 1,038 | V35: 471 | W35: 177 | X35: 31 | Y35: 10 | Z35: 1
A36: Devon Poor Law/Registration County | B36: #VALUE! | C36: M. | D36: 572,330 | E36: 272,063 | F36: 35,766 | G36: 33,687 | H36: 30,084 | I36: 27,190 | J36: 22,496 | K36: 19,501 | L36: 17,324 | M36: 15,488 | N36: 14,119 | O36: 12,238 | P36: 11,142 | Q36: 9,086 | R36: 8,648 | S36: 6,152 | T36: 4,540 | U36: 2,682 | V36: 1,320 | W36: 477 | X36: 98 | Y36: 23 | Z36: 2
C37: F. | D37: - | E37: 300,267 | F37: 35,565 | G37: 33,248 | H37: 29,627 | I37: 28,456 | J37: 27,383 | K37: 24,168 | L37: 20,876 | M37: 18,074 | N37: 16,169 | O37: 13,978 | P37: 12,703 | Q37: 10,214 | R37: 10,225 | S37: 7,592 | T37: 5,601 | U37: 3,481 | V37: 1,919 | W37: 735 | X37: 196 | Y37: 52 | Z37: 5
A38: Dorset Poor Law/Registration County | B38: #VALUE! | C38: M. | D38: 177,095 | E38: 85,828 | F38: 11,407 | G38: 10,626 | H38: 9,751 | I38: 9,018 | J38: 7,154 | K38: 5,961 | L38: 5,329 | M38: 4,774 | N38: 4,606 | O38: 3,745 | P38: 3,538 | Q38: 2,649 | R38: 2,391 | S38: 1,827 | T38: 1,564 | U38: 875 | V38: 424 | W38: 155 | X38: 30 | Y38: 4 | Z38: 0
C39: F. | D39: - | E39: 91,267 | F39: 11,478 | G39: 10,661 | H39: 9,428 | I39: 9,114 | J39: 8,120 | K39: 6,932 | L39: 5,931 | M39: 5,265 | N39: 4,930 | O39: 4,119 | P39: 3,736 | Q39: 2,950 | R39: 2,830 | S39: 2,208 | T39: 1,757 | U39: 1,028 | V39: 533 | W39: 182 | X39: 45 | Y39: 17 | Z39: 3
A40: East Riding Poor Law/Registration County | B40: #VALUE! | C40: M. | D40: 254,352 | E40: 124,572 | F40: 16,130 | G40: 14,355 | H40: 12,836 | I40: 12,577 | J40: 11,455 | K40: 10,190 | L40: 9,200 | M40: 7,831 | N40: 6,757 | O40: 5,633 | P40: 4,974 | Q40: 3,635 | R40: 3,202 | S40: 2,304 | T40: 1,742 | U40: 1,052 | V40: 500 | W40: 163 | X40: 31 | Y40: 3 | Z40: 2
C41: F. | D41: - | E41: 129,780 | F41: 15,994 | G41: 14,294 | H41: 12,871 | I41: 12,623 | J41: 12,488 | K41: 10,913 | L41: 9,372 | M41: 7,945 | N41: 7,211 | O41: 5,921 | P41: 5,437 | Q41: 4,060 | R41: 3,660 | S41: 2,694 | T41: 2,070 | U41: 1,270 | V41: 663 | W41: 233 | X41: 52 | Y41: 7 | Z41: 2
A42: Essex Poor Law/Registration County | B42: #VALUE! | C42: M. | D42: 344,130 | E42: 172,717 | F42: 23,375 | G42: 21,861 | H42: 19,261 | I42: 16,653 | J42: 14,642 | K42: 12,377 | L42: 11,538 | M42: 10,037 | N42: 9,127 | O42: 7,619 | P42: 7,033 | Q42: 5,444 | R42: 5,208 | S42: 3,352 | T42: 2,519 | U42: 1,574 | V42: 775 | W42: 260 | X42: 49 | Y42: 10 | Z42: 3
C43: F. | D43: - | E43: 171,413 | F43: 23,412 | G43: 21,317 | H43: 18,909 | I43: 15,497 | J43: 14,694 | K43: 13,205 | L43: 11,705 | M43: 9,970 | N43: 8,812 | O43: 7,412 | P43: 6,746 | Q43: 5,417 | R43: 5,211 | S43: 3,494 | T43: 2,608 | U43: 1,684 | V43: 896 | W43: 335 | X43: 76 | Y43: 13 | Z43: 0
A44: Gloucestershire Poor Law/Registration County | B44: #VALUE! | C44: M. | D44: 419,514 | E44: 198,569 | F44: 25,892 | G44: 23,939 | H44: 21,712 | I44: 19,706 | J44: 17,025 | K44: 14,630 | L44: 13,351 | M44: 11,621 | N44: 11,006 | O44: 9,364 | P44: 8,482 | Q44: 6,121 | R44: 5,796 | S44: 3,712 | T44: 3,207 | U44: 1,758 | V44: 877 | W44: 276 | X44: 75 | Y44: 15 | Z44: 4
C45: F. | D45: - | E45: 220,945 | F45: 25,549 | G45: 24,055 | H45: 21,380 | I45: 21,279 | J45: 21,724 | K45: 18,586 | L45: 15,826 | M45: 13,458 | N45: 12,646 | O45: 10,049 | P45: 9,510 | Q45: 7,059 | R45: 6,746 | S45: 4,808 | T45: 4,065 | U45: 2,351 | V45: 1,210 | W45: 462 | X45: 144 | Y45: 36 | Z45: 2
A46: Hampshire Poor Law/Registration County | B46: #VALUE! | C46: M. | D46: 402,016 | E46: 200,301 | F46: 26,138 | G46: 23,618 | H46: 20,902 | I46: 20,045 | J46: 18,523 | K46: 16,164 | L46: 14,164 | M46: 11,965 | N46: 10,472 | O46: 8,606 | P46: 7,666 | Q46: 6,095 | R46: 5,723 | S46: 4,122 | T46: 3,115 | U46: 1,767 | V46: 844 | W46: 288 | X46: 70 | Y46: 12 | Z46: 2
C47: F. | D47: - | E47: 201,715 | F47: 26,124 | G47: 23,234 | H47: 20,456 | I47: 18,866 | J47: 18,382 | K47: 16,871 | L47: 14,551 | M47: 12,445 | N47: 10,748 | O47: 8,850 | P47: 8,173 | Q47: 6,213 | R47: 6,052 | S47: 4,166 | T47: 3,186 | U47: 1,935 | V47: 996 | W47: 349 | X47: 96 | Y47: 21 | Z47: 1
A48: Herefordshire Poor Law/Registration County | B48: #VALUE! | C48: M. | D48: 99,120 | E48: 49,809 | F48: 6,000 | G48: 5,773 | H48: 5,172 | I48: 4,803 | J48: 4,077 | K48: 3,466 | L48: 3,242 | M48: 2,976 | N48: 2,884 | O48: 2,523 | P48: 2,193 | Q48: 1,807 | R48: 1,696 | S48: 1,168 | T48: 1,015 | U48: 602 | V48: 280 | W48: 113 | X48: 16 | Y48: 3 | Z48: 0
C49: F. | D49: - | E49: 49,311 | F49: 5,906 | G49: 5,589 | H49: 5,134 | I49: 4,423 | J49: 4,046 | K49: 3,597 | L49: 3,247 | M49: 2,904 | N49: 2,718 | O49: 2,334 | P49: 2,235 | Q49: 1,673 | R49: 1,741 | S49: 1,330 | T49: 1,111 | U49: 695 | V49: 415 | W49: 143 | X49: 56 | Y49: 14 | Z49: 0
A50: Hertfordshire Poor Law/Registration County | B50: #VALUE! | C50: M. | D50: 173,962 | E50: 86,465 | F50: 11,730 | G50: 10,979 | H50: 9,867 | I50: 8,805 | J50: 7,459 | K50: 6,325 | L50: 5,530 | M50: 4,990 | N50: 4,528 | O50: 3,816 | P50: 3,431 | Q50: 2,652 | R50: 2,318 | S50: 1,591 | T50: 1,302 | U50: 666 | V50: 330 | W50: 116 | X50: 27 | Y50: 3 | Z50: 0
...

Sheet clean
C1: Under | D1: 5-- | E1: 10-- | F1: 15-- | G1: 20-- | H1: 25-- | I1: 30-- | J1: 35-- | K1: 40-- | L1: 45-- | M1: 50-- | N1: 55-- | O1: 60-- | P1: 65-- | Q1: 70-- | R1: 75-- | S1: 80-- | T1: 85-- | U1: 90-- | V1: 95-- | W1: 100 and upwds
C2: 5 Years. | D2: [4] | E2: [5] | F2: [6] | G2: [7] | H2: [8] | I2: [9] | J2: [10] | K2: [11] | L2: [12] | M2: [13] | N2: [14] | O2: [15] | P2: [16] | Q2: [17] | R2: [18] | S2: [19] | T2: [20] | U2: [21] | V2: [22] | W2: [23]
C3: [3]
C5: 5 | D5: =C5+5 -> 10 | E5: =D5+5 -> 15 | F5: =E5+5 -> 20 | G5: =F5+5 -> 25 | H5: =G5+5 -> 30 | I5: =H5+5 -> 35 | J5: =I5+5 -> 40 | K5: =J5+5 -> 45 | ... V5: =U5+5 -> 100 | W5: 100
A6: where | B6: sex | C6: ="t_"&C5 -> t_5 | D6: ="t_"&D5 -> t_10 | E6: ="t_"&E5 -> t_15 | F6: ="t_"&F5 -> t_20 | G6: ="t_"&G5 -> t_25 | H6: ="t_"&H5 -> t_30 | I6: ="t_"&I5 -> t_35 | J6: ="t_"&J5 -> t_40 | ... V6: ="t_"&V5 -> t_100 | W6: ="t_"&W5&"_plus" -> t_100_plus
A7: London Poor Law/Registration County | B7: M. | C7: =original!F62 -> 146,449 | D7: =original!G62 -> 121,254 | E7: =original!H62 -> 107,231 | F7: =original!I62 -> 99,079 | G7: =original!J62 -> 108,081 | H7: =original!K62 -> 101,886 | I7: =original!L62 -> 93,308 | J7: =original!M62 -> 77,028 | ... W7: =original!Z62 -> 10
A8: London Poor Law/Registration County | B8: F. | C8: =original!F63 -> 147,113 | D8: =original!G63 -> 122,394 | E8: =original!H63 -> 109,138 | F8: =original!I63 -> 114,615 | G8: =original!J63 -> 133,320 | H8: =original!K63 -> 124,746 | I8: =original!L63 -> 108,183 | J8: =original!M63 -> 87,560 | ... W8: =original!Z63 -> 17
